<?xml version="1.0"?>

<robot name="bumperbot" xmlns:xacro="https://www.ros.org/wiki/xacro">

    <xacro:arg name="is_ignition" default="true"/>

    <!-- Include Gazebo Parameters -->
    <xacro:include filename="$(find bumperbot_description)/urdf/bumperbot_gazebo.xacro"/>

    <!-- ROS2 Control -->
    <xacro:include filename="$(find bumperbot_description)/urdf/bumperbot_ros2_control.xacro"/>

    <link name="base_footprint"/>

    <link name="base_link">
        <inertial>
            <origin xyz="0 0 0.04" rpy="0.0 0.25 0.3"/>
            <mass value="8.2573504e-01"/>
            <inertia ixx="2.2124416e-02" ixy="-1.2294101e-04" ixz="3.4938785e-04" 
                    iyy="2.1193702e-02" iyz="-5.0120904e-05" izz="2.0064271e-02"/>
        </inertial>
        <visual>
            <origin rpy="0 0 0" xyz="0 0 0"/>
            <geometry>
                <mesh filename="package://bumperbot_description/meshes/base_link.STL"/>
            </geometry>
            <material name="blue">
                <color rgba="0 0 1 1" />
            </material> 
        </visual>
        <collision>
            <origin rpy="0 0 0" xyz="0 0 0"/>
            <geometry>
                <mesh filename="package://bumperbot_description/meshes/base_link.STL"/>
            </geometry>
        </collision>
    </link>

    <joint name="base_joint" type="fixed">
        <parent link="base_footprint"/>
        <child link="base_link"/>
        <origin rpy="0 0 0" xyz="0 0 0.033"/>
    </joint>

    <link name="wheel_right_link">
        <inertial>
            <origin xyz="0 -0.014 0" rpy="0 0 0"/>
            <mass value="0.0530086090966721"/>
            <inertia ixx="1.88176298336665E-05" ixy="-4.8444933029987E-10" ixz="1.88163708851143E-08" 
                    iyy="3.11510738647764E-05" iyz="-6.93560663069607E-11" izz="1.8801969558182E-05"/>
        </inertial>
        <visual>
            <origin rpy="1.57 0 0" xyz="0 0 0"/>
            <geometry>
                <mesh filename="package://bumperbot_description/meshes/wheel_right_link.STL"/>
            </geometry>
            <material name="black">
                <color rgba="0 0 0 .9" />
            </material>
        </visual>
        <collision>
        <origin rpy="1.57 0 0" xyz="0 -0.015 0"/> 
            <geometry>
                <sphere radius="0.033"/>
            </geometry>
        </collision>
    </link>

    <joint name="wheel_right_joint" type="continuous">
        <parent link="base_link"/>
        <child link="wheel_right_link"/>
        <axis xyz="0 1 0"/>
        <origin rpy="0 0 0" xyz="0 -0.070 0"/>
    </joint>

    <link name="wheel_left_link">
        <inertial>
            <origin xyz="0 0.014 0" rpy="0 0 0"/>
            <mass value="0.0530086043217644"/>
            <inertia ixx="1.8792911368909E-05" ixy="3.31256392204584E-10" ixz="-1.14082001662767E-08" 
                    iyy="3.11510738759073E-05" iyz="-3.60499245082192E-10" izz="1.88266886146847E-05"/>
        </inertial>
        <visual>
            <origin rpy="-1.57 0 0" xyz="0 0 0"/>
            <geometry>
                <mesh filename="package://bumperbot_description/meshes/wheel_left_link.STL"/>
            </geometry>
            <material name="black">
                <color rgba="0 0 0 0.9" />
            </material>
        </visual>
        <collision>
        <origin rpy="-1.57 0 0" xyz="0 0.015 0"/> 
            <geometry>
                <sphere radius="0.033"/>
            </geometry>
        </collision>
    </link>

    <joint name="wheel_left_joint" type="continuous">
        <parent link="base_link"/>
        <child link="wheel_left_link"/>
        <axis xyz="0 1 0"/>
        <origin rpy="0 0 0" xyz="0 0.070 0"/>
    </joint>

    <link name="caster_front_link">
        <inertial>
            <origin xyz="3.89968128948481E-07 2.40073004698083E-07 0.00219173397061506" rpy="0 0 0"/>
            <mass value="1.0"/>
            <inertia ixx="0.01" ixy="-0" ixz="0" 
                    iyy="0.01" iyz="0" izz="0.01"/>
        </inertial>
        <visual>
        <origin rpy="0 0 0" xyz="0 0 0"/>
            <geometry>
                <!-- <mesh filename="package://bumperbot_description/meshes/caster_front_link.STL"/> -->
                <sphere radius="0.0075"  />
            </geometry>
            <material name="green">
                <color rgba="0 1 0 1" />
            </material>
        <collision>
            <origin rpy="0 0 0" xyz="0 0 0"/> 
            <geometry>
                <sphere radius="0.0075"/>
            </geometry>
        </collision>
        </visual>
    </link>

    <joint name="caster_front_joint" type="fixed">
        <parent link="base_link"/>
        <child link="caster_front_link"/>
        <origin rpy="0 0 0" xyz="0.04755 0 -0.0275"/>
    </joint>

    <link name="caster_rear_link">
        <inertial>
            <origin xyz="3.8996812895542E-07 2.40073004698083E-07 0.00219173397061509" rpy="0 0 0"/>
            <mass value="1.0"/>
            <inertia ixx="0.01" ixy="-0" ixz="0" 
                    iyy="0.01" iyz="0" izz="0.01"/>
        </inertial>
        <visual>
        <origin rpy="0 0 0" xyz="0 0 0"/>
            <geometry>
                <!-- <mesh filename="package://bumperbot_description/meshes/caster_rear_link.STL"/> -->
                <sphere radius="0.0075"/>
            </geometry>
            <material name="green">
                <color rgba="0 1 0 1" />
            </material>
        </visual>
        <collision>
            <origin rpy="0 0 0" xyz="0 0 0"/> 
            <geometry>
                <sphere radius="0.0075"/>
            </geometry>
        </collision>
    </link>

    <joint name="caster_rear_joint" type="fixed">
        <parent link="base_link"/>
        <child link="caster_rear_link"/>
        <origin rpy="0 0 0" xyz="-0.04755 0 -0.0275"/>
    </joint>

    <!-- <link name="can_link">
        <visual>
            <origin rpy="1.57 0 0" xyz="-0.03 0.03 0"/>
            <geometry>
                <mesh filename="package://bumperbot_description/meshes/can.STL"/>
            </geometry>
        </visual>
    </link>

    <joint name="can_joint" type="fixed">
        <parent link="base_link"/>
        <child link="can_link"/>
        <origin rpy="0 0 0" xyz="0 0 0.078"/>
    </joint> -->

    <link name="imu_link">
        <inertial>
            <origin xyz="-0.00552433659106688 0.000168210391520346 0.000514000497342681" rpy="0 0 0" />
            <mass value="0.000528415362211671"/>
            <inertia ixx="1.46176048428261E-08" ixy="1.40015117949421E-10" ixz="-1.99633872937403E-12"
                     iyy="8.59662482954888E-09" iyz="7.52375112767959E-12"
                     izz="2.30279421279312E-08"/>
        </inertial>
        <visual>
            <origin xyz="0 0 0" rpy="0 0 0"/>
            <geometry>
                <mesh filename="package://bumperbot_description/meshes/imu_link.STL"/>
            </geometry>
            <material name="">
                <color rgba="0.792156862745098 0.819607843137255 0.933333333333333 1"/>
            </material>
        </visual>
        <collision>
            <origin xyz="0 0 0" rpy="0 0 0"/>
            <geometry>
                <mesh filename="package://bumperbot_description/meshes/imu_link.STL"/>
            </geometry>
        </collision>
    </link>

    <joint name="imu_joint" type="fixed">
        <origin rpy="0 0 0" xyz="0 0 0.0698986241758014"/>
        <parent link="base_link"/>
        <child link="imu_link"/>
        <axis xyz="0 0 0"/>
    </joint>

</robot>